Workbook

Sheet Données_immobilier
A1: Salaire net avant impots annuel à T0 | B1: =12*2000 -> 24000 | D1: Table des impots
A2: augmentation annuelle moyenne | B2: 1 | D2: 11294 | E2: 0
A3: Inflation annuelle moyenne | B3: 1.02 | D3: 28797 | E3: 0.11
A4: Prix d'achat du bien | B4: =2100*30 -> 63000 | D4: 82341 | E4: 0.3
A5: Augmentation moyenne du prix du bien | B5: =1.014 -> 1.014 | D5: 177106 | E5: 0.41
A6: Evolution annuelle du loyer | B6: =1.014 -> 1.014 | E6: 0.45
A7: Argent de départ | B7: 10000
A8: Apport pour le prêt | B8: 10000
A9: Argent emprunté | B9: =B4*1.08-B8 -> 58040
A10: Taux assurance | B10: 0.001
A11: Taux du prêt | B11: 0.05
A12: Durée de l'emprunt | B12: =C12-0.0001 -> 9.9999 | C12: 10 | D12: <- Durée de l'emprunt à remplir, en années
A13: Montant total assurance | B13: =B10*B12*B9 -> 580.3942
A14: mensualités | B14: =B9*(B11/12)/(1-(1+B11/12)^(-12*B12))+B13/B12/12 -> 620.44566
A15: Coût total de l'emprunt | B15: =B14*12*B12 -> 74452.735
A16: Loyer mensuel | B16: 500
A17: Taux d'occupation du logement | B17: =11/12 -> 0.91666667 | C17: 11 mois dans l'année
A18: Prix des charges et entretien | B18: =0.01 -> 0.01 | C18: % de la valeur du logement
A19: Investissement à T0 | B19: =B7-B8 -> 0 | C19: Ce qu'il reste de l'argent pas mis dans le prêt
A20: Plus value annuelle moyenne NASDAQ | B20: =1+C20*(1-0.172)*(1-0.003) -> 1.0577861 | C20: 0.07 | D20: <- croissance annuelle nasdaq - CSG - frais
A21: Plus value si investissement mensuel | B21: =1+(B20-1)/2 -> 1.0288931
L23: Loyer + dépense moyenne par mois cette année (allez on dit que la corée c'est que tous les 3 ans)
A24: Année | B24: Salaire touché cette année | C24: Prix du loyer | D24: Loyers | E24: Revenus net imposables | F24: Revenus après abattement de 10% | G24: Impots sur le revenu | H24: Valeur logement | I24: Charges annuelles | J24: Mensualités | K24: Avec déduction des charges et mensualités | L24: Coût de la vie / mois | M24: En comptant de quoi vivre | N24: Reste à payer sur l'emprunt | O24: Valeur actions NASDAQ | P24: Argent investi dans le NASDAQ | Q24: Investissement locatif | R24: Inflation | S24: Full NASDAQ | T24: Locatif / inflation | U24: NASDAQ / inflation
A25: 1 | B25: =B1*$B$2 -> 24000 | C25: =B16 -> 500 | D25: =C25*$B$17*12 -> 5500 | E25: =B25+0.5*D25 -> 26750 | F25: =E25*0.9 -> 24075 | G25: =MAX(F25-$D$5,0)*$E$6+MAX(MIN(F25,$D$5)-$D$4,0)*$E$5+MAX(MIN(F25,$D$4)-$D$3,0)*$E$4+MAX(MIN(F25,$D$3)-$D$2,0)*$E$3 -> 1405.91 | H25: =B4*$B$5 -> 63882 | I25: =$B$18*H25+$B$17*12*50*$B$3+H25*0.03 -> 3116.28 | J25: =$B$14*(MIN(A25-$B$12,0)/(A25-$B$12)) -> 620.44566 | K25: =B25+D25-G25-I25-12*J25 -> 17532.462 | L25: =1100+900 -> 2000 | M25: =K25-L25*12 -> -6467.538 | N25: =B15-12*$B$14 -> 67007.387 | O25: =B19*$B$20+M25*$B$21 -> -6654.4049 | P25: =B19 -> 0 | Q25: =(H25+O25-N25)/1000 -> -9.7797922 | R25: =données_NASDAQ!J23 -> 9.0550034 | S25: =données_NASDAQ!I23 -> 9.4114463 | T25: =Q25/R25 -> -1.0800429 | U25: =S25/R25 -> 1.0393642
A26: 2 | B26: =B25*$B$2 -> 24000 | C26: =C25*$B$6 -> 507 | D26: =C26*$B$17*12 -> 5577 | E26: =B26+0.5*D26 -> 26788.5 | F26: =E26*0.9 -> 24109.65 | G26: =MAX(F26-$D$5,0)*$E$6+MAX(MIN(F26,$D$5)-$D$4,0)*$E$5+MAX(MIN(F26,$D$4)-$D$3,0)*$E$4+MAX(MIN(F26,$D$3)-$D$2,0)*$E$3 -> 1409.7215 | H26: =H25*$B$5 -> 64776.348 | I26: =$B$18*H26+$B$17*12*50*$B$3+H26*0.03 -> 3152.0539 | J26: =$B$14*(MIN(A25-$B$12,0)/(A25-$B$12)) -> 620.44566 | K26: =B26+D26-G26-I26-12*J26 -> 17569.877 | L26: =L25*$B$3 -> 2040 | M26: =K26-L26*12 -> -6910.1234 | N26: =N25-12*$B$14 -> 59562.039 | O26: =O25*$B$20+M26*$B$21 -> -14148.715 | P26: =P25+M26 -> -6910.1234 | Q26: =(H26+O26-N26)/1000 -> -8.9344065 | R26: =données_NASDAQ!J24 -> 7.6063069 | S26: =données_NASDAQ!I24 -> 8.2950137 | T26: =Q26/R26 -> -1.174605 | U26: =S26/R26 -> 1.0905442
A27: 3 | B27: =B26*$B$2 -> 24000 | C27: =C26*$B$6 -> 514.098 | D27: =C27*$B$17*12 -> 5655.078 | E27: =B27+0.5*D27 -> 26827.539 | F27: =E27*0.9 -> 24144.785 | G27: =MAX(F27-$D$5,0)*$E$6+MAX(MIN(F27,$D$5)-$D$4,0)*$E$5+MAX(MIN(F27,$D$4)-$D$3,0)*$E$4+MAX(MIN(F27,$D$3)-$D$2,0)*$E$3 -> 1413.5864 | H27: =H26*$B$5 -> 65683.217 | I27: =$B$18*H27+$B$17*12*50*$B$3+H27*0.03 -> 3188.3287 | J27: =$B$14*(MIN(A26-$B$12,0)/(A26-$B$12)) -> 620.44566 | K27: =B27+D27-G27-I27-12*J27 -> 17607.815 | L27: =L26*$B$3 -> 2080.8 | M27: =K27-L27*12 -> -7361.785 | N27: =N26-12*$B$14 -> 52116.691 | O27: =O26*$B$20+M27*$B$21 -> -22540.804 | P27: =P26+M27 -> -14271.908 | Q27: =(H27+O27-N27)/1000 -> -8.9742785 | R27: =données_NASDAQ!J25 -> 5.6341404 | S27: =données_NASDAQ!I25 -> 6.6103207 | T27: =Q27/R27 -> -1.592839 | U27: =S27/R27 -> 1.1732616
A28: 4 | B28: =B27*$B$2 -> 24000 | C28: =C27*$B$6 -> 521.29537 | D28: =C28*$B$17*12 -> 5734.2491 | E28: =B28+0.5*D28 -> 26867.125 | F28: =E28*0.9 -> 24180.412 | G28: =MAX(F28-$D$5,0)*$E$6+MAX(MIN(F28,$D$5)-$D$4,0)*$E$5+MAX(MIN(F28,$D$4)-$D$3,0)*$E$4+MAX(MIN(F28,$D$3)-$D$2,0)*$E$3 -> 1417.5053 | H28: =H27*$B$5 -> 66602.782 | I28: =$B$18*H28+$B$17*12*50*$B$3+H28*0.03 -> 3225.1113 | J28: =$B$14*(MIN(A27-$B$12,0)/(A27-$B$12)) -> 620.44566 | K28: =B28+D28-G28-I28-12*J28 -> 17646.285 | L28: =L27*$B$3 -> 2122.416 | M28: =K28-L28*12 -> -7822.7075 | N28: =N27-12*$B$14 -> 44671.343 | O28: =O27*$B$20+M28*$B$21 -> -31892.079 | P28: =P27+M28 -> -22094.616 | Q28: =(H28+O28-N28)/1000 -> -9.9606405 | R28: =données_NASDAQ!J26 -> 3.1181447 | S28: =données_NASDAQ!I26 -> 4.3144549 | T28: =Q28/R28 -> -3.1944125 | U28: =S28/R28 -> 1.3836609
A29: 5 | B29: =B28*$B$2 -> 24000 | C29: =C28*$B$6 -> 528.59351 | D29: =C29*$B$17*12 -> 5814.5286 | E29: =B29+0.5*D29 -> 26907.264 | F29: =E29*0.9 -> 24216.538 | G29: =MAX(F29-$D$5,0)*$E$6+MAX(MIN(F29,$D$5)-$D$4,0)*$E$5+MAX(MIN(F29,$D$4)-$D$3,0)*$E$4+MAX(MIN(F29,$D$3)-$D$2,0)*$E$3 -> 1421.4792 | H29: =H28*$B$5 -> 67535.221 | I29: =$B$18*H29+$B$17*12*50*$B$3+H29*0.03 -> 3262.4088 | J29: =$B$14*(MIN(A28-$B$12,0)/(A28-$B$12)) -> 620.44566 | K29: =B29+D29-G29-I29-12*J29 -> 17685.293 | L29: =L28*$B$3 -> 2164.8643 | M29: =K29-L29*12 -> -8293.0792 | N29: =N28-12*$B$14 -> 37225.995 | O29: =O28*$B$20+M29*$B$21 -> -42267.69 | P29: =P28+M29 -> -30387.695 | Q29: =(H29+O29-N29)/1000 -> -11.958465 | R29: =données_NASDAQ!J27 -> 0.037355429 | S29: =données_NASDAQ!I27 -> 1.3618226 | T29: =Q29/R29 -> -320.12655 | U29: =S29/R29 -> 36.455814
A30: 6 | B30: =B29*$B$2 -> 24000 | C30: =C29*$B$6 -> 535.99382 | D30: =C30*$B$17*12 -> 5895.932 | E30: =B30+0.5*D30 -> 26947.966 | F30: =E30*0.9 -> 24253.169 | G30: =MAX(F30-$D$5,0)*$E$6+MAX(MIN(F30,$D$5)-$D$4,0)*$E$5+MAX(MIN(F30,$D$4)-$D$3,0)*$E$4+MAX(MIN(F30,$D$3)-$D$2,0)*$E$3 -> 1425.5086 | H30: =H29*$B$5 -> 68480.714 | I30: =$B$18*H30+$B$17*12*50*$B$3+H30*0.03 -> 3300.2286 | J30: =$B$14*(MIN(A29-$B$12,0)/(A29-$B$12)) -> 620.44566 | K30: =B30+D30-G30-I30-12*J30 -> 17724.847 | L30: =L29*$B$3 -> 2208.1616 | M30: =K30-L30*12 -> -8773.0925 | N30: =N29-12*$B$14 -> 29780.647 | O30: =O29*$B$20+M30*$B$21 -> -53736.75 | P30: =P29+M30 -> -39160.788 | Q30: =(H30+O30-N30)/1000 -> -15.036683 | R30: =données_NASDAQ!J28 -> -3.6298127 | S30: =données_NASDAQ!I28 -> -2.2960103 | T30: =Q30/R30 -> 4.1425508 | U30: =S30/R30 -> 0.63254235
A31: 7 | B31: =B30*$B$2 -> 24000 | C31: =C30*$B$6 -> 543.49773 | D31: =C31*$B$17*12 -> 5978.475 | E31: =B31+0.5*D31 -> 26989.238 | F31: =E31*0.9 -> 24290.314 | G31: =MAX(F31-$D$5,0)*$E$6+MAX(MIN(F31,$D$5)-$D$4,0)*$E$5+MAX(MIN(F31,$D$4)-$D$3,0)*$E$4+MAX(MIN(F31,$D$3)-$D$2,0)*$E$3 -> 1429.5945 | H31: =H30*$B$5 -> 69439.444 | I31: =$B$18*H31+$B$17*12*50*$B$3+H31*0.03 -> 3338.5778 | J31: =$B$14*(MIN(A30-$B$12,0)/(A30-$B$12)) -> 620.44566 | K31: =B31+D31-G31-I31-12*J31 -> 17764.955 | L31: =L30*$B$3 -> 2252.3248 | M31: =K31-L31*12 -> -9262.9433 | N31: =N30-12*$B$14 -> 22335.299 | O31: =O30*$B$20+M31*$B$21 -> -66372.566 | P31: =P30+M31 -> -48423.731 | Q31: =(H31+O31-N31)/1000 -> -19.268422 | R31: =données_NASDAQ!J29 -> -7.9055826 | S31: =données_NASDAQ!I29 -> -6.710486 | T31: =Q31/R31 -> 2.4373184 | U31: =S31/R31 -> 0.84882877
A32: 8 | B32: =B31*$B$2 -> 24000 | C32: =C31*$B$6 -> 551.1067 | D32: =C32*$B$17*12 -> 6062.1737 | E32: =B32+0.5*D32 -> 27031.087 | F32: =E32*0.9 -> 24327.978 | G32: =MAX(F32-$D$5,0)*$E$6+MAX(MIN(F32,$D$5)-$D$4,0)*$E$5+MAX(MIN(F32,$D$4)-$D$3,0)*$E$4+MAX(MIN(F32,$D$3)-$D$2,0)*$E$3 -> 1433.7376 | H32: =H31*$B$5 -> 70411.596 | I32: =$B$18*H32+$B$17*12*50*$B$3+H32*0.03 -> 3377.4638 | J32: =$B$14*(MIN(A31-$B$12,0)/(A31-$B$12)) -> 620.44566 | K32: =B32+D32-G32-I32-12*J32 -> 17805.624 | L32: =L31*$B$3 -> 2297.3713 | M32: =K32-L32*12 -> -9762.8318 | N32: =N31-12*$B$14 -> 14889.951 | O32: =O31*$B$20+M32*$B$21 -> -80252.889 | P32: =P31+M32 -> -58186.563 | Q32: =(H32+O32-N32)/1000 -> -24.731245 | R32: =données_NASDAQ!J30 -> -12.812831 | S32: =données_NASDAQ!I30 -> -11.936234 | T32: =Q32/R32 -> 1.9301935 | U32: =S32/R32 -> 0.93158437
A33: 9 | B33: =B32*$B$2 -> 24000 | C33: =C32*$B$6 -> 558.82219 | D33: =C33*$B$17*12 -> 6147.0441 | E33: =B33+0.5*D33 -> 27073.522 | F33: =E33*0.9 -> 24366.17 | G33: =MAX(F33-$D$5,0)*$E$6+MAX(MIN(F33,$D$5)-$D$4,0)*$E$5+MAX(MIN(F33,$D$4)-$D$3,0)*$E$4+MAX(MIN(F33,$D$3)-$D$2,0)*$E$3 -> 1437.9387 | H33: =H32*$B$5 -> 71397.359 | I33: =$B$18*H33+$B$17*12*50*$B$3+H33*0.03 -> 3416.8943 | J33: =$B$14*(MIN(A32-$B$12,0)/(A32-$B$12)) -> 620.44566 | K33: =B33+D33-G33-I33-12*J33 -> 17846.863 | L33: =L32*$B$3 -> 2343.3188 | M33: =K33-L33*12 -> -10272.962 | N33: =N32-12*$B$14 -> 7444.6034 | O33: =O32*$B$20+M33*$B$21 -> -95460.172 | P33: =P32+M33 -> -68459.525 | Q33: =(H33+O33-N33)/1000 -> -31.507417 | R33: =données_NASDAQ!J31 -> -18.375108 | S33: =données_NASDAQ!I31 -> -18.031257 | T33: =Q33/R33 -> 1.7146793 | U33: =S33/R33 -> 0.9812871
A34: 10 | B34: =B33*$B$2 -> 24000 | C34: =C33*$B$6 -> 566.6457 | D34: =C34*$B$17*12 -> 6233.1027 | E34: =B34+0.5*D34 -> 27116.551 | F34: =E34*0.9 -> 24404.896 | G34: =MAX(F34-$D$5,0)*$E$6+MAX(MIN(F34,$D$5)-$D$4,0)*$E$5+MAX(MIN(F34,$D$4)-$D$3,0)*$E$4+MAX(MIN(F34,$D$3)-$D$2,0)*$E$3 -> 1442.1986 | H34: =H33*$B$5 -> 72396.922 | I34: =$B$18*H34+$B$17*12*50*$B$3+H34*0.03 -> 3456.8769 | J34: =$B$14*(MIN(A33-$B$12,0)/(A33-$B$12)) -> 620.44566 | K34: =B34+D34-G34-I34-12*J34 -> 17888.679 | L34: =L33*$B$3 -> 2390.1851 | M34: =K34-L34*12 -> -10793.542 | N34: =MAX(N33-12*$B$14,0) -> 0 | O34: =O33*$B$20+M34*$B$21 -> -112081.85 | P34: =P33+M34 -> -79253.067 | Q34: =(H34+O34-N34)/1000 -> -39.684924 | R34: =données_NASDAQ!J32 -> -24.616651 | S34: =données_NASDAQ!I32 -> -25.057133 | T34: =Q34/R34 -> 1.6121171 | U34: =S34/R34 -> 1.0178937
A35: 11 | B35: =B34*$B$2 -> 24000 | C35: =C34*$B$6 -> 574.57874 | D35: =C35*$B$17*12 -> 6320.3662 | E35: =B35+0.5*D35 -> 27160.183 | F35: =E35*0.9 -> 24444.165 | G35: =MAX(F35-$D$5,0)*$E$6+MAX(MIN(F35,$D$5)-$D$4,0)*$E$5+MAX(MIN(F35,$D$4)-$D$3,0)*$E$4+MAX(MIN(F35,$D$3)-$D$2,0)*$E$3 -> 1446.5181 | H35: =H34*$B$5 -> 73410.478 | I35: =$B$18*H35+$B$17*12*50*$B$3+H35*0.03 -> 3497.4191 | J35: =$B$14*(MIN(A34-$B$12,0)/(A34-$B$12)) -> 0 | K35: =B35+D35-G35-I35-12*J35 -> 25376.429 | L35: =L34*$B$3 -> 2437.9888 | M35: =K35-L35*12 -> -3879.4372 | N35: =MAX(N34-12*$B$14,0) -> 0 | O35: =O34*$B$20+M35*$B$21 -> -122550.15 | P35: =P34+M35 -> -83132.504 | Q35: =(H35+O35-N35)/1000 -> -49.139668 | R35: =données_NASDAQ!J33 -> -31.562405 | S35: =données_NASDAQ!I33 -> -33.079227 | T35: =Q35/R35 -> 1.5569051 | U35: =S35/R35 -> 1.0480579
A36: 12 | B36: =B35*$B$2 -> 24000 | C36: =C35*$B$6 -> 582.62284 | D36: =C36*$B$17*12 -> 6408.8513 | E36: =B36+0.5*D36 -> 27204.426 | F36: =E36*0.9 -> 24483.983 | G36: =MAX(F36-$D$5,0)*$E$6+MAX(MIN(F36,$D$5)-$D$4,0)*$E$5+MAX(MIN(F36,$D$4)-$D$3,0)*$E$4+MAX(MIN(F36,$D$3)-$D$2,0)*$E$3 -> 1450.8981 | H36: =H35*$B$5 -> 74438.225 | I36: =$B$18*H36+$B$17*12*50*$B$3+H36*0.03 -> 3538.529 | J36: =$B$14*(MIN(A35-$B$12,0)/(A35-$B$12)) -> 0 | K36: =B36+D36-G36-I36-12*J36 -> 25419.424 | L36: =L35*$B$3 -> 2486.7486 | M36: =K36-L36*12 -> -4421.5593 | N36: =MAX(N35-12*$B$14,0) -> 0 | O36: =O35*$B$20+M36*$B$21 -> -134181.16 | P36: =P35+M36 -> -87554.063 | Q36: =(H36+O36-N36)/1000 -> -59.74293 | R36: =données_NASDAQ!J34 -> -39.238043 | S36: =données_NASDAQ!I34 -> -42.166909 | T36: =Q36/R36 -> 1.5225767 | U36: =S36/R36 -> 1.0746435
A37: 13 | B37: =B36*$B$2 -> 24000 | C37: =C36*$B$6 -> 590.77956 | D37: =C37*$B$17*12 -> 6498.5752 | E37: =B37+0.5*D37 -> 27249.288 | F37: =E37*0.9 -> 24524.359 | G37: =MAX(F37-$D$5,0)*$E$6+MAX(MIN(F37,$D$5)-$D$4,0)*$E$5+MAX(MIN(F37,$D$4)-$D$3,0)*$E$4+MAX(MIN(F37,$D$3)-$D$2,0)*$E$3 -> 1455.3395 | H37: =H36*$B$5 -> 75480.36 | I37: =$B$18*H37+$B$17*12*50*$B$3+H37*0.03 -> 3580.2144 | J37: =$B$14*(MIN(A36-$B$12,0)/(A36-$B$12)) -> 0 | K37: =B37+D37-G37-I37-12*J37 -> 25463.021 | L37: =L36*$B$3 -> 2536.4836 | M37: =K37-L37*12 -> -4974.7817 | N37: =MAX(N36-12*$B$14,0) -> 0 | O37: =O36*$B$20+M37*$B$21 -> -147053.48 | P37: =P36+M37 -> -92528.845 | Q37: =(H37+O37-N37)/1000 -> -71.573122 | R37: =données_NASDAQ!J35 -> -47.669982 | S37: =données_NASDAQ!I35 -> -52.393797 | T37: =Q37/R37 -> 1.5014296 | U37: =S37/R37 -> 1.0990941
A38: 14 | B38: =B37*$B$2 -> 24000 | C38: =C37*$B$6 -> 599.05048 | D38: =C38*$B$17*12 -> 6589.5553 | E38: =B38+0.5*D38 -> 27294.778 | F38: =E38*0.9 -> 24565.3 | G38: =MAX(F38-$D$5,0)*$E$6+MAX(MIN(F38,$D$5)-$D$4,0)*$E$5+MAX(MIN(F38,$D$4)-$D$3,0)*$E$4+MAX(MIN(F38,$D$3)-$D$2,0)*$E$3 -> 1459.843 | H38: =H37*$B$5 -> 76537.085 | I38: =$B$18*H38+$B$17*12*50*$B$3+H38*0.03 -> 3622.4834 | J38: =$B$14*(MIN(A37-$B$12,0)/(A37-$B$12)) -> 0 | K38: =B38+D38-G38-I38-12*J38 -> 25507.229 | L38: =L37*$B$3 -> 2587.2133 | M38: =K38-L38*12 -> -5539.3303 | N38: =MAX(N37-12*$B$14,0) -> 0 | O38: =O37*$B$20+M38*$B$21 -> -161250.51 | P38: =P37+M38 -> -98068.175 | Q38: =(H38+O38-N38)/1000 -> -84.713426 | R38: =données_NASDAQ!J36 -> -56.885403 | S38: =données_NASDAQ!I36 -> -63.838002 | T38: =Q38/R38 -> 1.4891944 | U38: =S38/R38 -> 1.1222212
A39: 15 | B39: =B38*$B$2 -> 24000 | C39: =C38*$B$6 -> 607.43719 | D39: =C39*$B$17*12 -> 6681.809 | E39: =B39+0.5*D39 -> 27340.905 | F39: =E39*0.9 -> 24606.814 | G39: =MAX(F39-$D$5,0)*$E$6+MAX(MIN(F39,$D$5)-$D$4,0)*$E$5+MAX(MIN(F39,$D$4)-$D$3,0)*$E$4+MAX(MIN(F39,$D$3)-$D$2,0)*$E$3 -> 1464.4095 | H39: =H38*$B$5 -> 77608.605 | I39: =$B$18*H39+$B$17*12*50*$B$3+H39*0.03 -> 3665.3442 | J39: =$B$14*(MIN(A38-$B$12,0)/(A38-$B$12)) -> 0 | K39: =B39+D39-G39-I39-12*J39 -> 25552.055 | L39: =L38*$B$3 -> 2638.9575 | M39: =K39-L39*12 -> -6115.435 | N39: =MAX(N38-12*$B$14,0) -> 0 | O39: =O38*$B$20+M39*$B$21 -> -176860.68 | P39: =P38+M39 -> -104183.61 | Q39: =(H39+O39-N39)/1000 -> -99.252076 | R39: =données_NASDAQ!J37 -> -66.912272 | S39: =données_NASDAQ!I37 -> -76.582395 | T39: =Q39/R39 -> 1.4833165 | U39: =S39/R39 -> 1.1445194
A40: 16 | B40: =B39*$B$2 -> 24000 | C40: =C39*$B$6 -> 615.94131 | D40: =C40*$B$17*12 -> 6775.3544 | E40: =B40+0.5*D40 -> 27387.677 | F40: =E40*0.9 -> 24648.909 | G40: =MAX(F40-$D$5,0)*$E$6+MAX(MIN(F40,$D$5)-$D$4,0)*$E$5+MAX(MIN(F40,$D$4)-$D$3,0)*$E$4+MAX(MIN(F40,$D$3)-$D$2,0)*$E$3 -> 1469.04 | H40: =H39*$B$5 -> 78695.125 | I40: =$B$18*H40+$B$17*12*50*$B$3+H40*0.03 -> 3708.805 | J40: =$B$14*(MIN(A39-$B$12,0)/(A39-$B$12)) -> 0 | K40: =B40+D40-G40-I40-12*J40 -> 25597.509 | L40: =L39*$B$3 -> 2691.7367 | M40: =K40-L40*12 -> -6703.3308 | N40: =MAX(N39-12*$B$14,0) -> 0 | O40: =O39*$B$20+M40*$B$21 -> -193977.78 | P40: =P39+M40 -> -110886.94 | Q40: =(H40+O40-N40)/1000 -> -115.28266 | R40: =données_NASDAQ!J38 -> -77.779363 | S40: =données_NASDAQ!I38 -> -90.714886 | T40: =Q40/R40 -> 1.4821754 | U40: =S40/R40 -> 1.1663105
A41: 17 | B41: =B40*$B$2 -> 24000 | C41: =C40*$B$6 -> 624.56448 | D41: =C41*$B$17*12 -> 6870.2093 | E41: =B41+0.5*D41 -> 27435.105 | F41: =E41*0.9 -> 24691.594 | G41: =MAX(F41-$D$5,0)*$E$6+MAX(MIN(F41,$D$5)-$D$4,0)*$E$5+MAX(MIN(F41,$D$4)-$D$3,0)*$E$4+MAX(MIN(F41,$D$3)-$D$2,0)*$E$3 -> 1473.7354 | H41: =H40*$B$5 -> 79796.857 | I41: =$B$18*H41+$B$17*12*50*$B$3+H41*0.03 -> 3752.8743 | J41: =$B$14*(MIN(A40-$B$12,0)/(A40-$B$12)) -> 0 | K41: =B41+D41-G41-I41-12*J41 -> 25643.6 | L41: =L40*$B$3 -> 2745.5714 | M41: =K41-L41*12 -> -7303.2572 | N41: =MAX(N40-12*$B$14,0) -> 0 | O41: =O40*$B$20+M41*$B$21 -> -212701.28 | P41: =P40+M41 -> -118190.2 | Q41: =(H41+O41-N41)/1000 -> -132.90442 | R41: =données_NASDAQ!J39 -> -89.516272 | S41: =données_NASDAQ!I39 -> -106.32872 | T41: =Q41/R41 -> 1.4846957 | U41: =S41/R41 -> 1.1878144
...

Sheet données_NASDAQ
A1: Salaire net avant impots annuel à T0 | B1: =Données_immobilier!B1 -> 24000 | D1: Table des impots
A2: augmentation annuelle moyenne | B2: =Données_immobilier!B2 -> 1 | D2: 11294 | E2: 0
A3: Inflation annuelle moyenne | B3: =Données_immobilier!B3 -> 1.02 | D3: 28797 | E3: 0.11
A4: Prix d'achat du bien | B4: =Données_immobilier!B4 -> 63000 | D4: 82341 | E4: 0.3
A5: Augmentation moyenne du prix du bien | B5: =Données_immobilier!B5 -> 1.014 | D5: 177106 | E5: 0.41
A6: Evolution annuelle du loyer | B6: =Données_immobilier!B6 -> 1.014 | E6: 0.45
A7: Argent de départ | B7: =Données_immobilier!B7 -> 10000
A8: Apport pour le prêt | B8: =Données_immobilier!B8 -> 10000
A9: Argent emprunté | B9: =Données_immobilier!B9 -> 58040
A10: Taux du prêt avec assurance | B10: =Données_immobilier!B11 -> 0.05
A11: Durée de l'emprunt | B11: =Données_immobilier!B12 -> 9.9999
A12: Coût total de l'emprunt | B12: =Données_immobilier!$B$15 -> 74452.735
A13: mensualités | B13: =Données_immobilier!B14 -> 620.44566
A14: Loyer mensuel | B14: =Données_immobilier!B16 -> 500
A15: Taux d'occupation du logement | B15: =Données_immobilier!B17 -> 0.91666667 | C15: 11 mois dans l'année
A16: Prix des charges et entretien | B16: =Données_immobilier!B18 -> 0.01 | C16: % de la valeur du logement
A17: Investissement à T0 | B17: =Données_immobilier!B19 -> 0 | C17: Ce qu'il reste de l'argent pas mis dans le prêt
A18: Plus value annuelle moyenne NASDAQ | B18: =Données_immobilier!B20 -> 1.0577861
A19: Plus value si investissement mensuel | B19: =Données_immobilier!B21 -> 1.0288931
H21: Loyer + dépense moyenne par mois cette année (allez on dit que la corée c'est que tous les 3 ans)
A22: Année | B22: Salaire touché cette année | C22: Revenus net imposables | D22: Revenus après abattement de 10% | E22: Impots sur le revenu | F22: Avec déduction des impots | G22: Coût de la vie / mois | H22: En comptant de quoi vivre | I22: Valeur actions NASDAQ | J22: Inflation
A23: 1 | B23: =B1*$B$2 -> 24000 | C23: =B23 -> 24000 | D23: =C23*0.9 -> 21600 | E23: =MAX(D23-$D$5,0)*$E$6+MAX(MIN(D23,$D$5)-$D$4,0)*$E$5+MAX(MIN(D23,$D$4)-$D$3,0)*$E$4+MAX(MIN(D23,$D$3)-$D$2,0)*$E$3 -> 1133.66 | F23: =B23-E23 -> 22866.34 | G23: =1100+900 -> 2000 | H23: =(F23-G23*12)/1000 -> -1.13366 | I23: =B7*$B$18/1000+H23*$B$19 -> 9.4114463 | J23: =B7*$B$3/1000+H23*(1+($B$3-1)/2) -> 9.0550034
A24: 2 | B24: =B23*$B$2 -> 24000 | C24: =B24 -> 24000 | D24: =C24*0.9 -> 21600 | E24: =MAX(D24-$D$5,0)*$E$6+MAX(MIN(D24,$D$5)-$D$4,0)*$E$5+MAX(MIN(D24,$D$4)-$D$3,0)*$E$4+MAX(MIN(D24,$D$3)-$D$2,0)*$E$3 -> 1133.66 | F24: =B24-E24 -> 22866.34 | G24: =G23*$B$3 -> 2040 | H24: =(F24-G24*12)/1000 -> -1.61366 | I24: =I23*$B$18+H24*$B$19 -> 8.2950137 | J24: =J23*$B$3+H24*(1+($B$3-1)/2) -> 7.6063069
A25: 3 | B25: =B24*$B$2 -> 24000 | C25: =B25 -> 24000 | D25: =C25*0.9 -> 21600 | E25: =MAX(D25-$D$5,0)*$E$6+MAX(MIN(D25,$D$5)-$D$4,0)*$E$5+MAX(MIN(D25,$D$4)-$D$3,0)*$E$4+MAX(MIN(D25,$D$3)-$D$2,0)*$E$3 -> 1133.66 | F25: =B25-E25 -> 22866.34 | G25: =G24*$B$3 -> 2080.8 | H25: =(F25-G25*12)/1000 -> -2.10326 | I25: =I24*$B$18+H25*$B$19 -> 6.6103207 | J25: =J24*$B$3+H25*(1+($B$3-1)/2) -> 5.6341404
A26: 4 | B26: =B25*$B$2 -> 24000 | C26: =B26 -> 24000 | D26: =C26*0.9 -> 21600 | E26: =MAX(D26-$D$5,0)*$E$6+MAX(MIN(D26,$D$5)-$D$4,0)*$E$5+MAX(MIN(D26,$D$4)-$D$3,0)*$E$4+MAX(MIN(D26,$D$3)-$D$2,0)*$E$3 -> 1133.66 | F26: =B26-E26 -> 22866.34 | G26: =G25*$B$3 -> 2122.416 | H26: =(F26-G26*12)/1000 -> -2.602652 | I26: =I25*$B$18+H26*$B$19 -> 4.3144549 | J26: =J25*$B$3+H26*(1+($B$3-1)/2) -> 3.1181447
A27: 5 | B27: =B26*$B$2 -> 24000 | C27: =B27 -> 24000 | D27: =C27*0.9 -> 21600 | E27: =MAX(D27-$D$5,0)*$E$6+MAX(MIN(D27,$D$5)-$D$4,0)*$E$5+MAX(MIN(D27,$D$4)-$D$3,0)*$E$4+MAX(MIN(D27,$D$3)-$D$2,0)*$E$3 -> 1133.66 | F27: =B27-E27 -> 22866.34 | G27: =G26*$B$3 -> 2164.8643 | H27: =(F27-G27*12)/1000 -> -3.1120318 | I27: =I26*$B$18+H27*$B$19 -> 1.3618226 | J27: =J26*$B$3+H27*(1+($B$3-1)/2) -> 0.037355429
A28: 6 | B28: =B27*$B$2 -> 24000 | C28: =B28 -> 24000 | D28: =C28*0.9 -> 21600 | E28: =MAX(D28-$D$5,0)*$E$6+MAX(MIN(D28,$D$5)-$D$4,0)*$E$5+MAX(MIN(D28,$D$4)-$D$3,0)*$E$4+MAX(MIN(D28,$D$3)-$D$2,0)*$E$3 -> 1133.66 | F28: =B28-E28 -> 22866.34 | G28: =G27*$B$3 -> 2208.1616 | H28: =(F28-G28*12)/1000 -> -3.6315993 | I28: =I27*$B$18+H28*$B$19 -> -2.2960103 | J28: =J27*$B$3+H28*(1+($B$3-1)/2) -> -3.6298127
A29: 7 | B29: =B28*$B$2 -> 24000 | C29: =B29 -> 24000 | D29: =C29*0.9 -> 21600 | E29: =MAX(D29-$D$5,0)*$E$6+MAX(MIN(D29,$D$5)-$D$4,0)*$E$5+MAX(MIN(D29,$D$4)-$D$3,0)*$E$4+MAX(MIN(D29,$D$3)-$D$2,0)*$E$3 -> 1133.66 | F29: =B29-E29 -> 22866.34 | G29: =G28*$B$3 -> 2252.3248 | H29: =(F29-G29*12)/1000 -> -4.1615581 | I29: =I28*$B$18+H29*$B$19 -> -6.710486 | J29: =J28*$B$3+H29*(1+($B$3-1)/2) -> -7.9055826
A30: 8 | B30: =B29*$B$2 -> 24000 | C30: =B30 -> 24000 | D30: =C30*0.9 -> 21600 | E30: =MAX(D30-$D$5,0)*$E$6+MAX(MIN(D30,$D$5)-$D$4,0)*$E$5+MAX(MIN(D30,$D$4)-$D$3,0)*$E$4+MAX(MIN(D30,$D$3)-$D$2,0)*$E$3 -> 1133.66 | F30: =B30-E30 -> 22866.34 | G30: =G29*$B$3 -> 2297.3713 | H30: =(F30-G30*12)/1000 -> -4.702116 | I30: =I29*$B$18+H30*$B$19 -> -11.936234 | J30: =J29*$B$3+H30*(1+($B$3-1)/2) -> -12.812831
A31: 9 | B31: =B30*$B$2 -> 24000 | C31: =B31 -> 24000 | D31: =C31*0.9 -> 21600 | E31: =MAX(D31-$D$5,0)*$E$6+MAX(MIN(D31,$D$5)-$D$4,0)*$E$5+MAX(MIN(D31,$D$4)-$D$3,0)*$E$4+MAX(MIN(D31,$D$3)-$D$2,0)*$E$3 -> 1133.66 | F31: =B31-E31 -> 22866.34 | G31: =G30*$B$3 -> 2343.3188 | H31: =(F31-G31*12)/1000 -> -5.2534851 | I31: =I30*$B$18+H31*$B$19 -> -18.031257 | J31: =J30*$B$3+H31*(1+($B$3-1)/2) -> -18.375108
A32: 10 | B32: =B31*$B$2 -> 24000 | C32: =B32 -> 24000 | D32: =C32*0.9 -> 21600 | E32: =MAX(D32-$D$5,0)*$E$6+MAX(MIN(D32,$D$5)-$D$4,0)*$E$5+MAX(MIN(D32,$D$4)-$D$3,0)*$E$4+MAX(MIN(D32,$D$3)-$D$2,0)*$E$3 -> 1133.66 | F32: =B32-E32 -> 22866.34 | G32: =G31*$B$3 -> 2390.1851 | H32: =(F32-G32*12)/1000 -> -5.8158816 | I32: =I31*$B$18+H32*$B$19 -> -25.057133 | J32: =J31*$B$3+H32*(1+($B$3-1)/2) -> -24.616651
A33: 11 | B33: =B32*$B$2 -> 24000 | C33: =B33 -> 24000 | D33: =C33*0.9 -> 21600 | E33: =MAX(D33-$D$5,0)*$E$6+MAX(MIN(D33,$D$5)-$D$4,0)*$E$5+MAX(MIN(D33,$D$4)-$D$3,0)*$E$4+MAX(MIN(D33,$D$3)-$D$2,0)*$E$3 -> 1133.66 | F33: =B33-E33 -> 22866.34 | G33: =G32*$B$3 -> 2437.9888 | H33: =(F33-G33*12)/1000 -> -6.3895261 | I33: =I32*$B$18+H33*$B$19 -> -33.079227 | J33: =J32*$B$3+H33*(1+($B$3-1)/2) -> -31.562405
A34: 12 | B34: =B33*$B$2 -> 24000 | C34: =B34 -> 24000 | D34: =C34*0.9 -> 21600 | E34: =MAX(D34-$D$5,0)*$E$6+MAX(MIN(D34,$D$5)-$D$4,0)*$E$5+MAX(MIN(D34,$D$4)-$D$3,0)*$E$4+MAX(MIN(D34,$D$3)-$D$2,0)*$E$3 -> 1133.66 | F34: =B34-E34 -> 22866.34 | G34: =G33*$B$3 -> 2486.7486 | H34: =(F34-G34*12)/1000 -> -6.9746434 | I34: =I33*$B$18+H34*$B$19 -> -42.166909 | J34: =J33*$B$3+H34*(1+($B$3-1)/2) -> -39.238043
A35: 13 | B35: =B34*$B$2 -> 24000 | C35: =B35 -> 24000 | D35: =C35*0.9 -> 21600 | E35: =MAX(D35-$D$5,0)*$E$6+MAX(MIN(D35,$D$5)-$D$4,0)*$E$5+MAX(MIN(D35,$D$4)-$D$3,0)*$E$4+MAX(MIN(D35,$D$3)-$D$2,0)*$E$3 -> 1133.66 | F35: =B35-E35 -> 22866.34 | G35: =G34*$B$3 -> 2536.4836 | H35: =(F35-G35*12)/1000 -> -7.5714631 | I35: =I34*$B$18+H35*$B$19 -> -52.393797 | J35: =J34*$B$3+H35*(1+($B$3-1)/2) -> -47.669982
... A52: 30 | B52: =B51*$B$2 -> 24000 | C52: =B52 -> 24000 | D52: =C52*0.9 -> 21600 | E52: =MAX(D52-$D$5,0)*$E$6+MAX(MIN(D52,$D$5)-$D$4,0)*$E$5+MAX(MIN(D52,$D$4)-$D$3,0)*$E$4+MAX(MIN(D52,$D$3)-$D$2,0)*$E$3 -> 1133.66 | F52: =B52-E52 -> 22866.34 | G52: =G51*$B$3 -> 3551.6894 | H52: =(F52-G52*12)/1000 -> -19.753933 | I52: =I51*$B$18+H52*$B$19 -> -498.43542 | J52: =J51*$B$3+H52*(1+($B$3-1)/2) -> -336.36072
